Workbook

Sheet README
A1: WMO 5 Oktober 2026 — Raw Chart Data
A2: Data mentah dan perhitungan untuk Exhibit 1–6 serta angka di teks halaman 1–3.
A4: Cara pakai
A5: Teks biru | B5: Data mentah yang disalin dari file sumber (ubah di sini kalau data diperbarui).
A6: Teks hitam | B6: Formula; ikut berubah otomatis.
A7: Teks hijau | B7: Link ke sheet lain.
A8: Isi kuning | B8: Angka kunci yang dikutip di teks WMO.
A10: Sheet | B10: Isi · Sumber
A11: Ex1_CME_Path | B11: Exhibit 1: jalur target rate CME (rata-rata tertimbang titik tengah) · Screenshot CME FedWatch 5 Okt 2026 (intraday, jam tidak tercatat)
A12: Ex2_UST_ACM | B12: Exhibit 2: UST 10YR vs ACM term premium + UST 2YR/2s10s · TIM - 4.xlsx (USGG10YR), TIM - 7.xlsx (ACMTP10, UST2Y)
A13: Ex3_SOX_Hyperscalers | B13: Exhibit 3: kinerja YTD SOX vs hyperscalers · TIM - 7.xlsx (SOX, Stocks; Alphabet = GOOG)
A14: Ex4_Hyperscaler_Bonds | B14: Exhibit 4: amount outstanding obligasi USD aktif per tahun terbit · TIM - 5.xlsx (Matrix)
A15: Ex5_FXR_USDIDR | B15: Exhibit 5: cadangan devisa vs USD/IDR akhir bulan · TIM - 7.xlsx (FX Reserve), TIM - 4.xlsx (USDIDR REGN)
A16: Ex6_Trade_Balance | B16: Exhibit 6: neraca dagang bulanan · TIM - 6.xlsx (ID TRADE BALANCE, USD mn)
A17: P2_Text_Data | B17: Data teks halaman 2: capex, EPS Micron & BEst, yield obligasi 2036 · TIM - 7.xlsx (CAPEX, MU), TIM - 4.xlsx Sheet2 (snapshot 5 Okt)
... A21: Catatan | B21: Cutoff data pasar 2 Oktober 2026. Yield & suku bunga dalam satuan persen (5,27 = 5,27%); probabilitas & return disimpan sebagai pecahan dan diformat %.
B22: TIM - 4.xlsx Sheet2 sudah berisi #NAME? (tersimpan ulang tanpa add-in Bloomberg); yield obligasi 2036 memakai nilai yang dibaca 5 Okt 2026.
B23: Sheet CAPEX blok kedua (tanpa label) tidak dipakai. Cadangan devisa terbaru: Agustus 2026.

Sheet Ex1_CME_Path
A1: Exhibit 1: CME-Implied Fed Target Rate Path by FOMC Meeting (%)
A2: Sumber: CME FedWatch conditional meeting probabilities (screenshot 5 Okt 2026, intraday; jam tidak tercatat). Titik tengah dalam %, probabilitas sebagai pecahan.
A4: Titik tengah rentang (%) | C4: 3.875 | D4: 4.125 | E4: 4.375 | F4: 4.625 | G4: 4.875 | H4: 5.125 | I4: 5.375 | J4: 5.625
A5: FOMC | B5: Tanggal rapat | C5: 375-400 | D5: 400-425 | E5: 425-450 | F5: 450-475 | G5: 475-500 | H5: 500-525 | I5: 525-550 | J5: 550-575 | K5: Total prob. | L5: P(target ≥4,00%) | M5: Implied midpoint (%)
A6: Oct-26 | B6: 46323 | C6: 0.795 | D6: 0.205 | K6: =SUM(C6:J6) -> 1 | L6: =SUM(D6:J6) -> 0.205 | M6: =SUMPRODUCT(C6:J6,$C$4:$J$4)/K6 -> 3.92625
A7: Dec-26 | B7: 46365 | C7: 0.183 | D7: 0.659 | E7: 0.158 | K7: =SUM(C7:J7) -> 1 | L7: =SUM(D7:J7) -> 0.817 | M7: =SUMPRODUCT(C7:J7,$C$4:$J$4)/K7 -> 4.11875
A8: Jan-27 | B8: 46414 | C8: 0.112 | D8: 0.473 | E8: 0.353 | F8: 0.062 | K8: =SUM(C8:J8) -> 1 | L8: =SUM(D8:J8) -> 0.888 | M8: =SUMPRODUCT(C8:J8,$C$4:$J$4)/K8 -> 4.21625
A9: Mar-27 | B9: 46463 | C9: 0.034 | D9: 0.222 | E9: 0.437 | F9: 0.264 | G9: 0.043 | K9: =SUM(C9:J9) -> 1 | L9: =SUM(D9:J9) -> 0.966 | M9: =SUMPRODUCT(C9:J9,$C$4:$J$4)/K9 -> 4.39
A10: Apr-27 | B10: 46505 | C10: 0.021 | D10: 0.15 | E10: 0.354 | F10: 0.331 | G10: 0.128 | H10: 0.016 | K10: =SUM(C10:J10) -> 1 | L10: =SUM(D10:J10) -> 0.979 | M10: =SUMPRODUCT(C10:J10,$C$4:$J$4)/K10 -> 4.48575
A11: Jun-27 | B11: 46547 | C11: 0.011 | D11: 0.092 | E11: 0.262 | F11: 0.341 | G11: 0.22 | H11: 0.067 | I11: 0.007 | K11: =SUM(C11:J11) -> 1 | L11: =SUM(D11:J11) -> 0.989 | M11: =SUMPRODUCT(C11:J11,$C$4:$J$4)/K11 -> 4.599
A12: Jul-27 | B12: 46596 | C12: 0.009 | D12: 0.076 | E12: 0.23 | F12: 0.326 | G12: 0.243 | H12: 0.096 | I12: 0.019 | J12: 0.001 | K12: =SUM(C12:J12) -> 1 | L12: =SUM(D12:J12) -> 0.991 | M12: =SUMPRODUCT(C12:J12,$C$4:$J$4)/K12 -> 4.64675
A13: Sep-27 | B13: 46645 | C13: 0.008 | D13: 0.065 | E13: 0.205 | F13: 0.31 | G13: 0.256 | H13: 0.12 | I13: 0.031 | J13: 0.004 | K13: =SUM(C13:J13) -> 0.999 | L13: =SUM(D13:J13) -> 0.991 | M13: =SUMPRODUCT(C13:J13,$C$4:$J$4)/K13 -> 4.6865616
A14: Oct-27 | B14: 46687 | C14: 0.007 | D14: 0.063 | E14: 0.198 | F14: 0.306 | G14: 0.259 | H14: 0.126 | I14: 0.035 | J14: 0.005 | K14: =SUM(C14:J14) -> 0.999 | L14: =SUM(D14:J14) -> 0.992 | M14: =SUMPRODUCT(C14:J14,$C$4:$J$4)/K14 -> 4.6978228
A15: Dec-27 | B15: 46729 | C15: 0.011 | D15: 0.072 | E15: 0.205 | F15: 0.302 | G15: 0.25 | H15: 0.12 | I15: 0.033 | J15: 0.005 | K15: =SUM(C15:J15) -> 0.998 | L15: =SUM(D15:J15) -> 0.987 | M15: =SUMPRODUCT(C15:J15,$C$4:$J$4)/K15 -> 4.6818637
A17: Catatan: rentang 525-550 dan 550-575 pada rapat Oktober kosong di screenshot (dibiarkan kosong, tidak diisi nol).

Sheet Ex2_UST_ACM
A1: Exhibit 2: UST 10YR Yield vs. ACM 10YR Term Premium (%)
A2: Sumber: Bloomberg USGG10YR Index (TIM - 4), ACMTP10 Index & USGG2YR (TIM - 7). Harian, 31 Des 2025 – 2 Okt 2026. Chart memakai 1 Jul – 2 Okt.
A4: Tanggal | B4: UST 10YR (%) | C4: ACM 10Y term premium (%) | D4: UST 2YR (%) | E4: 2s10s (bps) | G4: Ringkasan | H4: Tanggal awal | I4: Tanggal akhir | J4: UST 10YR Δ (bps) | K4: Term premium Δ (bps) | L4: Ekspektasi (sisa, bps) | M4: UST 2YR Δ (bps)
A5: 46022 | B5: 4.167 | C5: 0.7478 | D5: 3.473 | E5: =IF(OR(B5="",D5=""),"",(B5-D5)*100) -> 69.4 | G5: Pekan 25 Sep – 2 Okt | H5: 46290 | I5: 46297 | J5: =(INDEX($B$5:$B$194,MATCH(I5,$A$5:$A$194,0))-INDEX($B$5:$B$194,MATCH(H5,$A$5:$A$194,0)))*100 -> 11.02 | K5: =(INDEX($C$5:$C$194,MATCH(I5,$A$5:$A$194,0))-INDEX($C$5:$C$194,MATCH(H5,$A$5:$A$194,0)))*100 -> 14.22 | L5: =J5-K5 -> -3.2 | M5: =(INDEX($D$5:$D$194,MATCH(I5,$A$5:$A$194,0))-INDEX($D$5:$D$194,MATCH(H5,$A$5:$A$194,0)))*100 -> -2.69
A6: 46024 | B6: 4.1907 | C6: 0.7901 | D6: 3.4733 | E6: =IF(OR(B6="",D6=""),"",(B6-D6)*100) -> 71.74 | G6: 28 Sep – 2 Okt | H6: 46293 | I6: 46297 | J6: =(INDEX($B$5:$B$194,MATCH(I6,$A$5:$A$194,0))-INDEX($B$5:$B$194,MATCH(H6,$A$5:$A$194,0)))*100 -> 3.45 | K6: =(INDEX($C$5:$C$194,MATCH(I6,$A$5:$A$194,0))-INDEX($C$5:$C$194,MATCH(H6,$A$5:$A$194,0)))*100 -> 12.4 | L6: =J6-K6 -> -8.95 | M6: =(INDEX($D$5:$D$194,MATCH(I6,$A$5:$A$194,0))-INDEX($D$5:$D$194,MATCH(H6,$A$5:$A$194,0)))*100 -> -10.58
A7: 46027 | B7: 4.1612 | C7: 0.7758 | D7: 3.4508 | E7: =IF(OR(B7="",D7=""),"",(B7-D7)*100) -> 71.04 | G7: Sejak akhir Juni | H7: 46203 | I7: 46297 | J7: =(INDEX($B$5:$B$194,MATCH(I7,$A$5:$A$194,0))-INDEX($B$5:$B$194,MATCH(H7,$A$5:$A$194,0)))*100 -> 80.54 | K7: =(INDEX($C$5:$C$194,MATCH(I7,$A$5:$A$194,0))-INDEX($C$5:$C$194,MATCH(H7,$A$5:$A$194,0)))*100 -> 40.75 | L7: =J7-K7 -> 39.79 | M7: =(INDEX($D$5:$D$194,MATCH(I7,$A$5:$A$194,0))-INDEX($D$5:$D$194,MATCH(H7,$A$5:$A$194,0)))*100 -> 65.24
A8: 46028 | B8: 4.173 | C8: 0.7836 | D8: 3.4632 | E8: =IF(OR(B8="",D8=""),"",(B8-D8)*100) -> 70.98 | G8: YTD (31 Des 2025 – 2 Okt) | H8: 46022 | I8: 46297 | J8: =(INDEX($B$5:$B$194,MATCH(I8,$A$5:$A$194,0))-INDEX($B$5:$B$194,MATCH(H8,$A$5:$A$194,0)))*100 -> 110.36 | K8: =(INDEX($C$5:$C$194,MATCH(I8,$A$5:$A$194,0))-INDEX($C$5:$C$194,MATCH(H8,$A$5:$A$194,0)))*100 -> 16.59 | L8: =J8-K8 -> 93.77 | M8: =(INDEX($D$5:$D$194,MATCH(I8,$A$5:$A$194,0))-INDEX($D$5:$D$194,MATCH(H8,$A$5:$A$194,0)))*100 -> 135.17
A9: 46029 | B9: 4.1475 | C9: 0.731 | D9: 3.4695 | E9: =IF(OR(B9="",D9=""),"",(B9-D9)*100) -> 67.8
A10: 46030 | B10: 4.1672 | C10: 0.7531 | D10: 3.4881 | E10: =IF(OR(B10="",D10=""),"",(B10-D10)*100) -> 67.91
A11: 46031 | B11: 4.1653 | C11: 0.6983 | D11: 3.5321 | E11: =IF(OR(B11="",D11=""),"",(B11-D11)*100) -> 63.32 | G11: Level | H11: Tanggal | J11: Nilai
A12: 46034 | B12: 4.1752 | C12: 0.7134 | D12: 3.5343 | E12: =IF(OR(B12="",D12=""),"",(B12-D12)*100) -> 64.09 | G12: UST 10YR (%) | H12: 46297 | J12: =INDEX($B$5:$B$194,MATCH(H12,$A$5:$A$194,0)) -> 5.2706
A13: 46035 | B13: 4.1792 | C13: 0.7116 | D13: 3.5324 | E13: =IF(OR(B13="",D13=""),"",(B13-D13)*100) -> 64.68 | G13: Term premium ACM (%) | H13: 46297 | J13: =INDEX($C$5:$C$194,MATCH(H13,$A$5:$A$194,0)) -> 0.9137
A14: 46036 | B14: 4.132 | C14: 0.6791 | D14: 3.5097 | E14: =IF(OR(B14="",D14=""),"",(B14-D14)*100) -> 62.23 | G14: 2s10s 25 Sep (bps) | H14: 46290 | J14: =INDEX($E$5:$E$194,MATCH(H14,$A$5:$A$194,0)) -> 30.88
A15: 46037 | B15: 4.1694 | C15: 0.6602 | D15: 3.5641 | E15: =IF(OR(B15="",D15=""),"",(B15-D15)*100) -> 60.53 | G15: 2s10s 2 Okt (bps) | H15: 46297 | J15: =INDEX($E$5:$E$194,MATCH(H15,$A$5:$A$194,0)) -> 44.59
A16: 46038 | B16: 4.2229 | C16: 0.7027 | D16: 3.586 | E16: =IF(OR(B16="",D16=""),"",(B16-D16)*100) -> 63.69 | G16: Term premium tertinggi di data (%) | J16: =MAX(C5:C194) -> 0.9137
A17: 46042 | B17: 4.2925 | C17: 0.804 | D17: 3.5968 | E17: =IF(OR(B17="",D17=""),"",(B17-D17)*100) -> 69.57 | G17: Catatan: data ACMTP10 hanya tersedia sejak 6 Okt 2025, jadi 'tertinggi' berarti tertinggi dalam ±1 tahun.
A18: 46043 | B18: 4.2428 | C18: 0.7628 | D18: 3.5845 | E18: =IF(OR(B18="",D18=""),"",(B18-D18)*100) -> 65.83
A19: 46044 | B19: 4.2449 | C19: 0.7257 | D19: 3.6058 | E19: =IF(OR(B19="",D19=""),"",(B19-D19)*100) -> 63.91
A20: 46045 | B20: 4.2252 | C20: 0.7098 | D20: 3.594 | E20: =IF(OR(B20="",D20=""),"",(B20-D20)*100) -> 63.12
A21: 46048 | B21: 4.2113 | C21: 0.6801 | D21: 3.59 | E21: =IF(OR(B21="",D21=""),"",(B21-D21)*100) -> 62.13
A22: 46049 | B22: 4.2432 | C22: 0.7147 | D22: 3.5731 | E22: =IF(OR(B22="",D22=""),"",(B22-D22)*100) -> 67.01
A23: 46050 | B23: 4.2432 | C23: 0.7372 | D23: 3.5712 | E23: =IF(OR(B23="",D23=""),"",(B23-D23)*100) -> 67.2
A24: 46051 | B24: 4.2313 | C24: 0.7512 | D24: 3.5591 | E24: =IF(OR(B24="",D24=""),"",(B24-D24)*100) -> 67.22
A25: 46052 | B25: 4.2355 | C25: 0.7622 | D25: 3.5224 | E25: =IF(OR(B25="",D25=""),"",(B25-D25)*100) -> 71.31
A26: 46055 | B26: 4.2774 | C26: 0.7931 | D26: 3.5716 | E26: =IF(OR(B26="",D26=""),"",(B26-D26)*100) -> 70.58
A27: 46056 | B27: 4.2655 | C27: 0.7862 | D27: 3.5696 | E27: =IF(OR(B27="",D27=""),"",(B27-D27)*100) -> 69.59
A28: 46057 | B28: 4.2735 | C28: 0.7816 | D28: 3.5532 | E28: =IF(OR(B28="",D28=""),"",(B28-D28)*100) -> 72.03
A29: 46058 | B29: 4.1801 | C29: 0.7751 | D29: 3.4504 | E29: =IF(OR(B29="",D29=""),"",(B29-D29)*100) -> 72.97
... A194: 46297 | B194: 5.2706 | C194: 0.9137 | D194: 4.8247 | E194: =IF(OR(B194="",D194=""),"",(B194-D194)*100) -> 44.59

Sheet Ex3_SOX_Hyperscalers
A1: Exhibit 3: Semiconductors vs. Hyperscalers YTD Performance (%)
A2: Sumber: Bloomberg, TIM - 7.xlsx (SOX Index; GOOG, MSFT, AMZN, META, ORCL US Equity). Harga penutupan harian.
A4: Tanggal | B4: SOX | C4: Alphabet | D4: Microsoft | E4: Amazon | F4: Meta | G4: Oracle | J4: Tanggal dasar YTD | K4: 46022
A5: 46022 | B5: 7083.131 | C5: 313.8 | D5: 483.62 | E5: 230.82 | F5: 660.09 | G5: 194.91 | J5: Tanggal dasar 'sejak akhir Juni' | K5: 46203
A6: 46024 | B6: 7367.473 | C6: 315.32 | D6: 472.94 | E6: 226.5 | F6: 650.41 | G6: 195.71 | J6: Tanggal dasar 1W | K6: 46290
A7: 46027 | B7: 7446.454 | C7: 317.32 | D7: 472.85 | E7: 233.06 | F7: 658.79 | G7: 192.59 | J7: Tanggal akhir | K7: 46297
A8: 46028 | B8: 7650.929 | C8: 314.55 | D8: 478.51 | E8: 240.93 | F8: 660.62 | G8: 193.75
A9: 46029 | B9: 7574.872 | C9: 322.43 | D9: 483.47 | E9: 241.56 | F9: 648.69 | G9: 192.84 | J9: Seri | K9: YTD | L9: Sejak akhir Juni | M9: 1W
A10: 46030 | B10: 7436.098 | C10: 326.01 | D10: 478.11 | E10: 246.29 | F10: 646.06 | G10: 189.65 | J10: SOX | K10: =INDEX($B$5:$B$194,MATCH($K$7,$A$5:$A$194,0))/INDEX($B$5:$B$194,MATCH($K$4,$A$5:$A$194,0))-1 -> 0.85464168 | L10: =INDEX($B$5:$B$194,MATCH($K$7,$A$5:$A$194,0))/INDEX($B$5:$B$194,MATCH($K$5,$A$5:$A$194,0))-1 -> -0.077931713 | M10: =INDEX($B$5:$B$194,MATCH($K$7,$A$5:$A$194,0))/INDEX($B$5:$B$194,MATCH($K$6,$A$5:$A$194,0))-1 -> 0.036920245
A11: 46031 | B11: 7638.779 | C11: 329.14 | D11: 479.28 | E11: 247.38 | F11: 653.06 | G11: 198.52 | J11: Alphabet | K11: =INDEX($C$5:$C$194,MATCH($K$7,$A$5:$A$194,0))/INDEX($C$5:$C$194,MATCH($K$4,$A$5:$A$194,0))-1 -> 0.084608031 | L11: =INDEX($C$5:$C$194,MATCH($K$7,$A$5:$A$194,0))/INDEX($C$5:$C$194,MATCH($K$5,$A$5:$A$194,0))-1 -> -0.036736196 | M11: =INDEX($C$5:$C$194,MATCH($K$7,$A$5:$A$194,0))/INDEX($C$5:$C$194,MATCH($K$6,$A$5:$A$194,0))-1 -> -0.0021402603
A12: 46034 | B12: 7674.836 | C12: 332.73 | D12: 477.18 | E12: 246.47 | F12: 641.97 | G12: 204.68 | J12: Microsoft | K12: =INDEX($D$5:$D$194,MATCH($K$7,$A$5:$A$194,0))/INDEX($D$5:$D$194,MATCH($K$4,$A$5:$A$194,0))-1 -> 0.070117034 | L12: =INDEX($D$5:$D$194,MATCH($K$7,$A$5:$A$194,0))/INDEX($D$5:$D$194,MATCH($K$5,$A$5:$A$194,0))-1 -> 0.3874055 | M12: =INDEX($D$5:$D$194,MATCH($K$7,$A$5:$A$194,0))/INDEX($D$5:$D$194,MATCH($K$6,$A$5:$A$194,0))-1 -> 0.0026347909
A13: 46035 | B13: 7747.993 | C13: 336.43 | D13: 470.67 | E13: 242.6 | F13: 631.09 | G13: 202.29 | J13: Amazon | K13: =INDEX($E$5:$E$194,MATCH($K$7,$A$5:$A$194,0))/INDEX($E$5:$E$194,MATCH($K$4,$A$5:$A$194,0))-1 -> 0.08968027 | L13: =INDEX($E$5:$E$194,MATCH($K$7,$A$5:$A$194,0))/INDEX($E$5:$E$194,MATCH($K$5,$A$5:$A$194,0))-1 -> 0.055299152 | M13: =INDEX($E$5:$E$194,MATCH($K$7,$A$5:$A$194,0))/INDEX($E$5:$E$194,MATCH($K$6,$A$5:$A$194,0))-1 -> 0.0074097809
A14: 46036 | B14: 7701.475 | C14: 336.31 | D14: 459.38 | E14: 236.65 | F14: 615.52 | G14: 193.61 | J14: Meta | K14: =INDEX($F$5:$F$194,MATCH($K$7,$A$5:$A$194,0))/INDEX($F$5:$F$194,MATCH($K$4,$A$5:$A$194,0))-1 -> 0.10300111 | L14: =INDEX($F$5:$F$194,MATCH($K$7,$A$5:$A$194,0))/INDEX($F$5:$F$194,MATCH($K$5,$A$5:$A$194,0))-1 -> 0.29254913 | M14: =INDEX($F$5:$F$194,MATCH($K$7,$A$5:$A$194,0))/INDEX($F$5:$F$194,MATCH($K$6,$A$5:$A$194,0))-1 -> -0.031370566
A15: 46037 | B15: 7837.298 | C15: 333.16 | D15: 456.66 | E15: 238.18 | F15: 620.8 | G15: 189.85 | J15: Oracle | K15: =INDEX($G$5:$G$194,MATCH($K$7,$A$5:$A$194,0))/INDEX($G$5:$G$194,MATCH($K$4,$A$5:$A$194,0))-1 -> -0.26991945 | L15: =INDEX($G$5:$G$194,MATCH($K$7,$A$5:$A$194,0))/INDEX($G$5:$G$194,MATCH($K$5,$A$5:$A$194,0))-1 -> -0.029000341 | M15: =INDEX($G$5:$G$194,MATCH($K$7,$A$5:$A$194,0))/INDEX($G$5:$G$194,MATCH($K$6,$A$5:$A$194,0))-1 -> 0.037928519
A16: 46038 | B16: 7927.408 | C16: 330.34 | D16: 459.86 | E16: 239.12 | F16: 620.25 | G16: 191.09 | J16: Rata-rata 5 hyperscalers | K16: =AVERAGE(K11:K15) -> 0.015497398 | L16: =AVERAGE(L11:L15) -> 0.13390345 | M16: =AVERAGE(M11:M15) -> 0.0028924529
A17: 46042 | B17: 7794.19 | C17: 322.16 | D17: 454.52 | E17: 231 | F17: 604.12 | G17: 179.92
A18: 46043 | B18: 8042.07 | C18: 328.38 | D18: 444.11 | E18: 231.31 | F18: 612.96 | G18: 173.88 | J18: Chart (urutan WMO) | K18: YTD
A19: 46044 | B19: 8055.173 | C19: 330.84 | D19: 451.14 | E19: 234.34 | F19: 647.63 | G19: 178.18 | J19: SOX | K19: =K10 -> 0.85464168
A20: 46045 | B20: 7957.926 | C20: 328.43 | D20: 465.95 | E20: 239.16 | F20: 658.76 | G20: 177.16 | J20: Hyperscalers (avg.) | K20: =K16 -> 0.015497398
A21: 46048 | B21: 7927.041 | C21: 333.59 | D21: 470.28 | E21: 238.42 | F21: 672.36 | G21: 182.44 | J21: Meta | K21: =K14 -> 0.10300111
A22: 46049 | B22: 8117.181 | C22: 335 | D22: 480.58 | E22: 244.68 | F22: 672.97 | G22: 174.9 | J22: Amazon | K22: =K13 -> 0.08968027
A23: 46050 | B23: 8306.742 | C23: 336.28 | D23: 481.63 | E23: 243.01 | F23: 668.73 | G23: 172.8 | J23: Alphabet | K23: =K11 -> 0.084608031
A24: 46051 | B24: 8320.39 | C24: 338.66 | D24: 433.5 | E24: 241.73 | F24: 738.31 | G24: 169.01 | J24: Microsoft | K24: =K12 -> 0.070117034
A25: 46052 | B25: 7998.473 | C25: 338.53 | D25: 430.29 | E25: 239.3 | F25: 716.5 | G25: 164.58 | J25: Oracle | K25: =K15 -> -0.26991945
A26: 46055 | B26: 8134.488 | C26: 344.9 | D26: 423.37 | E26: 242.96 | F26: 706.41 | G26: 160.06
A27: 46056 | B27: 7966.334 | C27: 340.7 | D27: 411.21 | E27: 238.62 | F27: 691.7 | G27: 154.67
A28: 46057 | B28: 7619.156 | C28: 333.34 | D28: 414.19 | E28: 232.99 | F28: 668.99 | G28: 146.67
A29: 46058 | B29: 7614.638 | C29: 331.33 | D29: 393.67 | E29: 222.69 | F29: 670.21 | G29: 136.48
A30: 46059 | B30: 8048.625 | C30: 323.1 | D30: 401.14 | E30: 210.32 | F30: 661.46 | G30: 142.82
A31: 46062 | B31: 8162.58 | C31: 324.4 | D31: 413.6 | E31: 208.72 | F31: 677.22 | G31: 156.59
A32: 46063 | B32: 8107.132 | C32: 318.63 | D32: 413.27 | E32: 206.96 | F32: 670.72 | G32: 159.89
A33: 46064 | B33: 8291.861 | C33: 311.33 | D33: 404.37 | E33: 204.08 | F33: 668.69 | G33: 157.16
A34: 46065 | B34: 8084.7 | C34: 309.37 | D34: 401.84 | E34: 199.6 | F34: 649.81 | G34: 156.48
A35: 46066 | B35: 8137.859 | C35: 306.02 | D35: 401.32 | E35: 198.79 | F35: 639.77 | G35: 160.14
A36: 46070 | B36: 8136.045 | C36: 302.82 | D36: 396.86 | E36: 201.15 | F36: 639.29 | G36: 153.97
A37: 46071 | B37: 8214.354 | C37: 303.94 | D37: 399.6 | E37: 204.79 | F37: 643.22 | G37: 156.17
... A194: 46297 | B194: 13136.67 | C194: 340.35 | D194: 517.53 | E194: 251.52 | F194: 728.08 | G194: 142.3

Sheet Ex4_Hyperscaler_Bonds
A1: Exhibit 4: Hyperscaler USD Bonds Outstanding by Issue Year (USD Bn)
A2: Sumber: Bloomberg SRCH, TIM - 5.xlsx (Matrix): SUM of Amount Outstanding, obligasi USD korporasi aktif (208 seri), dibuat 5 Okt 2026. Bukan gross issuance.
A4: Tahun terbit (raw, USD) | B4: Amazon | C4: Alphabet | D4: Meta | E4: Oracle | F4: Microsoft | G4: Total (Bloomberg)
A5: 2025 | B5: 15000000000 | C5: 22500000000 | D5: 30000000000 | E5: 25750000000 | G5: 93250000000
A6: 2026 | B6: 62000000000 | C6: 45000000000 | D6: 25000000000 | E6: 25000000000 | G6: 157000000000
A8: USD Bn | B8: Amazon | C8: Alphabet | D8: Meta | E8: Oracle | F8: Microsoft | G8: Total (sum) | H8: Cek vs Bloomberg
A9: 2025 | B9: =IF(B5="",0,B5/1000000000) -> 15 | C9: =IF(C5="",0,C5/1000000000) -> 22.5 | D9: =IF(D5="",0,D5/1000000000) -> 30 | E9: =IF(E5="",0,E5/1000000000) -> 25.75 | F9: =IF(F5="",0,F5/1000000000) -> 0 | G9: =SUM(B9:F9) -> 93.25 | H9: =G9-G5/1000000000 -> 0
A10: 2026 YTD | B10: =IF(B6="",0,B6/1000000000) -> 62 | C10: =IF(C6="",0,C6/1000000000) -> 45 | D10: =IF(D6="",0,D6/1000000000) -> 25 | E10: =IF(E6="",0,E6/1000000000) -> 25 | F10: =IF(F6="",0,F6/1000000000) -> 0 | G10: =SUM(B10:F10) -> 157 | H10: =G10-G6/1000000000 -> 0
A11: Perubahan (USD Bn) | B11: =B10-B9 -> 47 | C11: =C10-C9 -> 22.5 | D11: =D10-D9 -> -5 | E11: =E10-E9 -> -0.75 | F11: =F10-F9 -> 0 | G11: =G10-G9 -> 63.75
A12: Perubahan (%) | G12: =G10/G9-1 -> 0.68364611
A13: Microsoft tidak punya amount outstanding untuk vintage 2025 & 2026 (sel kosong di Matrix).

Sheet Ex5_FXR_USDIDR
A1: Exhibit 5: Indonesia FX Reserves (USD Bn) vs. USD/IDR
A2: Sumber: Bloomberg — cadangan devisa (TIM - 7, FX Reserve; terbaru Agustus 2026), USDIDR REGN Curncy (TIM - 4). USD/IDR akhir bulan = observasi terakhir ≤ akhir bulan.
A4: Bulan | B4: Cadangan devisa (USD bn) | C4: USD/IDR akhir bulan | D4: Tanggal USD/IDR | F4: Ringkasan | G4: Nilai | I4: USD/IDR | J4: Nilai
A5: Oct-25 | B5: 149.9326 | C5: 16630 | D5: 45961 | F5: Cadangan devisa Agustus 2026 (USD bn) | G5: =B15 -> 146.5076 | I5: Penutupan 2 Okt 2026 | J5: =INDEX(G13:G191,MATCH(DATE(2026,10,2),F13:F191,0)) -> 17875
A6: Nov-25 | B6: 150.061 | C6: 16660 | D6: 45989 | F6: Cadangan devisa Desember 2025 (USD bn) | G6: =INDEX(B5:B15,MATCH("Dec-25",A5:A15,0)) -> 156.471 | I6: Penutupan 31 Des 2025 | J6: =INDEX(G13:G191,MATCH(DATE(2025,12,31),F13:F191,0)) -> 16690
A7: Dec-25 | B7: 156.471 | C7: 16690 | D7: 46022 | F7: Perubahan vs akhir 2025 (USD bn) | G7: =G5-G6 -> -9.9634 | I7: Pelemahan rupiah YTD | J7: =J5/J6-1 -> 0.071000599
A8: Jan-26 | B8: 154.5805 | C8: 16785 | D8: 46052 | F8: Terendah 2026 (USD bn) | G8: =MIN(B8:B15) -> 144.8984 | I8: Terendah September 2026 | J8: =_xlfn.MINIFS(G13:G191,F13:F191,">="&DATE(2026,9,1),F13:F191,"<="&DATE(2026,9,30)) -> 17513
A9: Feb-26 | B9: 151.9012 | C9: 16771 | D9: 46080 | F9: Bulan terendah | G9: =INDEX(A5:A15,MATCH(G8,B5:B15,0)) -> May-26 | I9: Tertinggi September 2026 | J9: =_xlfn.MAXIFS(G13:G191,F13:F191,">="&DATE(2026,9,1),F13:F191,"<="&DATE(2026,9,30)) -> 17975
A10: Mar-26 | B10: 148.1502 | C10: 16995 | D10: 46112 | I10: Puncak 2026 | J10: =_xlfn.MAXIFS(G13:G191,F13:F191,">="&DATE(2026,1,1)) -> 18178
A11: Apr-26 | B11: 146.202 | C11: 17353 | D11: 46142 | I11: Tanggal puncak 2026 | J11: =INDEX(F13:F191,MATCH(J10,G13:G191,0)) -> 46181
A12: May-26 | B12: 144.8984 | C12: 17874 | D12: 46171 | F12: Tanggal | G12: USD/IDR (harian)
A13: Jun-26 | B13: 145.5936 | C13: 17882 | D13: 46203 | F13: 46022 | G13: 16690
A14: Jul-26 | B14: 145.3438 | C14: 18000 | D14: 46234 | F14: 46024 | G14: 16725
A15: Aug-26 | B15: 146.5076 | C15: 17720 | D15: 46265 | F15: 46027 | G15: 16740
F16: 46028 | G16: 16750
F17: 46029 | G17: 16775
F18: 46030 | G18: 16793
F19: 46031 | G19: 16805
F20: 46034 | G20: 16833
F21: 46035 | G21: 16865
F22: 46036 | G22: 16860
F23: 46037 | G23: 16885
F24: 46041 | G24: 16942
F25: 46042 | G25: 16950
F26: 46043 | G26: 16935
F27: 46044 | G27: 16885
... F191: 46297 | G191: 17875

Sheet Ex6_Trade_Balance
A1: Exhibit 6: Indonesia Trade Balance (USD Bn)
A2: Sumber: Bloomberg, TIM - 6.xlsx (ID TRADE BALANCE, USD mn; identik dengan IDBALTOL Index di TIM - 4). Chart = 12 bulan terakhir (Sep-25 – Agu-26).
A4: Akhir bulan | B4: Trade balance (USD mn) | C4: Trade balance (USD bn) | D4: Label chart | F4: Ringkasan (USD bn) | G4: Nilai
A5: 45230 | B5: 3471.6 | C5: =B5/1000 -> 3.4716 | D5: =TEXT(A5,"mmm-yy") -> Oct-23 | F5: Agustus 2026 (terbaru) | G5: =C39 -> 3.5522
A6: 45260 | B6: 2409.5 | C6: =B6/1000 -> 2.4095 | D6: =TEXT(A6,"mmm-yy") -> Nov-23 | F6: Juli 2026 | G6: =C38 -> 0.1219
A7: 45291 | B7: 3284.5 | C7: =B7/1000 -> 3.2845 | D7: =TEXT(A7,"mmm-yy") -> Dec-23 | F7: Agustus 2025 | G7: =C27 -> 5.5733
A8: 45322 | B8: 1982.5 | C8: =B8/1000 -> 1.9825 | D8: =TEXT(A8,"mmm-yy") -> Jan-24 | F8: Surplus 12 bulan terakhir (Sep-25 – Agu-26) | G8: =SUM(C28:C39) -> 19.0469
A9: 45351 | B9: 841 | C9: =B9/1000 -> 0.841 | D9: =TEXT(A9,"mmm-yy") -> Feb-24 | F9: Surplus 12 bulan sebelumnya (Sep-24 – Agu-25) | G9: =SUM(C16:C27) -> 41.6692
A10: 45382 | B10: 4602.2 | C10: =B10/1000 -> 4.6022 | D10: =TEXT(A10,"mmm-yy") -> Mar-24 | F10: Januari–Agustus 2026 | G10: =SUMIFS(C5:C39,A5:A39,">="&DATE(2026,1,1),A5:A39,"<="&DATE(2026,8,31)) -> 7.2511
A11: 45412 | B11: 2699.7 | C11: =B11/1000 -> 2.6997 | D11: =TEXT(A11,"mmm-yy") -> Apr-24 | F11: Januari–Agustus 2025 | G11: =SUMIFS(C5:C39,A5:A39,">="&DATE(2025,1,1),A5:A39,"<="&DATE(2025,8,31)) -> 29.3469
A12: 45443 | B12: 2936.8 | C12: =B12/1000 -> 2.9368 | D12: =TEXT(A12,"mmm-yy") -> May-24 | F12: Perubahan Jan–Agu (YoY) | G12: =G10/G11-1 -> -0.75291768
A13: 45473 | B13: 2519 | C13: =B13/1000 -> 2.519 | D13: =TEXT(A13,"mmm-yy") -> Jun-24 | F13: Jumlah bulan defisit di data | G13: =COUNTIF(C5:C39,"<0") -> 2
A14: 45504 | B14: 671.2 | C14: =B14/1000 -> 0.6712 | D14: =TEXT(A14,"mmm-yy") -> Jul-24
A15: 45535 | B15: 2755.1 | C15: =B15/1000 -> 2.7551 | D15: =TEXT(A15,"mmm-yy") -> Aug-24
A16: 45565 | B16: 3176.7 | C16: =B16/1000 -> 3.1767 | D16: =TEXT(A16,"mmm-yy") -> Sep-24
A17: 45596 | B17: 2711 | C17: =B17/1000 -> 2.711 | D17: =TEXT(A17,"mmm-yy") -> Oct-24
A18: 45626 | B18: 4344.4 | C18: =B18/1000 -> 4.3444 | D18: =TEXT(A18,"mmm-yy") -> Nov-24
A19: 45657 | B19: 2090.2 | C19: =B19/1000 -> 2.0902 | D19: =TEXT(A19,"mmm-yy") -> Dec-24
A20: 45688 | B20: 3540.3 | C20: =B20/1000 -> 3.5403 | D20: =TEXT(A20,"mmm-yy") -> Jan-25
A21: 45716 | B21: 3155.6 | C21: =B21/1000 -> 3.1556 | D21: =TEXT(A21,"mmm-yy") -> Feb-25
A22: 45747 | B22: 4296.2 | C22: =B22/1000 -> 4.2962 | D22: =TEXT(A22,"mmm-yy") -> Mar-25
A23: 45777 | B23: 196.6 | C23: =B23/1000 -> 0.1966 | D23: =TEXT(A23,"mmm-yy") -> Apr-25
A24: 45808 | B24: 4311.6 | C24: =B24/1000 -> 4.3116 | D24: =TEXT(A24,"mmm-yy") -> May-25
A25: 45838 | B25: 4095.5 | C25: =B25/1000 -> 4.0955 | D25: =TEXT(A25,"mmm-yy") -> Jun-25
... A39: 46265 | B39: 3552.2 | C39: =B39/1000 -> 3.5522 | D39: =TEXT(A39,"mmm-yy") -> Aug-26

Sheet P2_Text_Data
A1: Data teks halaman 2: capex, Micron, yield obligasi 2036
A2: Sumber: TIM - 7.xlsx (CAPEX blok pertama, USD mn, tanda negatif = arus kas keluar; MU), TIM - 4.xlsx Sheet2 (snapshot 5 Okt 2026).
A4: Capex (USD mn, raw) | B4: Alphabet | C4: Microsoft | D4: Amazon | E4: Meta | F4: Total 4 (USD bn)
A5: Q4 2025 | B5: -27851 | C5: -29876 | D5: -39522 | E5: -21383 | F5: =-SUM(B5:E5)/1000 -> 118.632
A6: Q1 2026 | B6: -35674 | C6: -30876 | D6: -44203 | E6: -18997 | F6: =-SUM(B6:E6)/1000 -> 129.75
A7: Q2 2026 | B7: -44924 | C7: -35802 | D7: -54208 | E7: -30116 | F7: =-SUM(B7:E7)/1000 -> 165.05
A8: Pertumbuhan Q4-25 → Q2-26 | F8: =F7/F5-1 -> 0.39127723
A10: Oracle (kuartal fiskal) | B10: Capex (USD mn, raw) | C10: Capex (USD bn)
A11: 45991 | B11: -12033 | C11: =-B11/1000 -> 12.033
A12: 46081 | B12: -18635 | C12: =-B12/1000 -> 18.635
A13: 46173 | B13: -16493 | C13: =-B13/1000 -> 16.493
A14: 46265 | B14: -28499 | C14: =-B14/1000 -> 28.499
A15: Kelipatan Nov-25 → Agu-26 | C15: =C14/C11 -> 2.3684036
A17: Micron | B17: Nilai | C17: Keterangan
A18: EPS dasar kuartal terakhir (USD) | B18: 33.36 | C18: MU sheet, periode 30 Sep 2026
A19: EPS dasar setahun sebelumnya (USD) | B19: 2.86 | C19: MU sheet, periode 30 Sep 2025
A20: BEst EPS 29 Sep 2026 | B20: 156.532 | C20: Konsensus Bloomberg (horizon tidak tertulis)
A21: BEst EPS 2 Okt 2026 | B21: 169.893
A22: Revisi BEst EPS | B22: =B21/B20-1 -> 0.085356349
A24: Obligasi USD jatuh tempo 2036 | B24: Coupon (%) | C24: Maturity | D24: Rating (BBG composite) | E24: YTM mid (%)
A25: Alphabet Inc | B25: 4.8 | C25: 2/15/2036 | D25: AA | E25: 5.9222648
A26: Alphabet Inc | B26: 5.45 | C26: 8/15/2036 | D26: AA | E26: 5.9675361
A27: Amazon.com Inc | B27: 4.875 | C27: 3/13/2036 | D27: AA- | E27: 5.9990147
A28: Amazon.com Inc | B28: 5.3 | C28: 7/9/2036 | D28: AA- | E28: 6.0110363
A29: Meta Platforms Inc | B29: 5.25 | C29: 5/15/2036 | D29: AA- | E29: 6.1987023
A30: Microsoft Corp | B30: 3.45 | C30: 8/8/2036 | D30: AAA | E30: 5.5770173
A31: Oracle Corp | B31: 5.7 | C31: 2/4/2036 | D31: BBB- | E31: 7.4604158
A32: Oracle Corp | B32: 3.85 | C32: 7/15/2036 | D32: BBB- | E32: 7.3959811
A33: Terendah / tertinggi (%) | D33: =MIN(E25:E32) -> 5.5770173 | E33: =MAX(E25:E32) -> 7.4604158
A34: Selisih Oracle vs Microsoft (bps) | E34: =(E33-D33)*100 -> 188.33985

Sheet P3_SBN_CPI
A1: Data teks halaman 3: spread FR 10YR vs UST 10YR, inflasi, real yield
A2: Sumber: TIM - 7.xlsx (GIDN10 = yield SBN 10 tahun rupiah; IDCPI); UST 10YR dari sheet Ex2_UST_ACM.
A4: Tanggal | B4: FR 10YR / GIDN10 (%) | C4: UST 10YR (%) | D4: Spread (bps) | F4: Ringkasan | G4: Nilai
A5: 46021 | B5: 6.086 | C5: =IFERROR(INDEX(Ex2_UST_ACM!$B$5:$B$194,MATCH(A5,Ex2_UST_ACM!$A$5:$A$194,0)),"") | D5: =IF(C5="","",(B5-C5)*100) | F5: Spread tertinggi 2026 (bps) | G5: =MAX(D5:D179) -> 298.39
A6: 46024 | B6: 6.046 | C6: =IFERROR(INDEX(Ex2_UST_ACM!$B$5:$B$194,MATCH(A6,Ex2_UST_ACM!$A$5:$A$194,0)),"") -> 4.1907 | D6: =IF(C6="","",(B6-C6)*100) -> 185.53 | F6: Tanggal spread tertinggi | G6: =INDEX(A5:A179,MATCH(G5,D5:D179,0)) -> 46184
A7: 46027 | B7: 6.09 | C7: =IFERROR(INDEX(Ex2_UST_ACM!$B$5:$B$194,MATCH(A7,Ex2_UST_ACM!$A$5:$A$194,0)),"") -> 4.1612 | D7: =IF(C7="","",(B7-C7)*100) -> 192.88 | F7: Spread 2 Okt 2026 (bps) | G7: =INDEX(D5:D179,MATCH(DATE(2026,10,2),A5:A179,0)) -> 189.54
A8: 46028 | B8: 6.097 | C8: =IFERROR(INDEX(Ex2_UST_ACM!$B$5:$B$194,MATCH(A8,Ex2_UST_ACM!$A$5:$A$194,0)),"") -> 4.173 | D8: =IF(C8="","",(B8-C8)*100) -> 192.4 | F8: Perubahan UST 10YR 11 Jun → 2 Okt (bps) | G8: =(INDEX(C5:C179,MATCH(DATE(2026,10,2),A5:A179,0))-INDEX(C5:C179,MATCH(DATE(2026,6,11),A5:A179,0)))*100 -> 80.95
A9: 46029 | B9: 6.103 | C9: =IFERROR(INDEX(Ex2_UST_ACM!$B$5:$B$194,MATCH(A9,Ex2_UST_ACM!$A$5:$A$194,0)),"") -> 4.1475 | D9: =IF(C9="","",(B9-C9)*100) -> 195.55 | F9: Perubahan FR 10YR 11 Jun → 2 Okt (bps) | G9: =(INDEX(B5:B179,MATCH(DATE(2026,10,2),A5:A179,0))-INDEX(B5:B179,MATCH(DATE(2026,6,11),A5:A179,0)))*100 -> -27.9
A10: 46030 | B10: 6.127 | C10: =IFERROR(INDEX(Ex2_UST_ACM!$B$5:$B$194,MATCH(A10,Ex2_UST_ACM!$A$5:$A$194,0)),"") -> 4.1672 | D10: =IF(C10="","",(B10-C10)*100) -> 195.98 | F10: FR 10YR 2 Okt 2026 (%) | G10: =INDEX(B5:B179,MATCH(DATE(2026,10,2),A5:A179,0)) -> 7.166
A11: 46031 | B11: 6.133 | C11: =IFERROR(INDEX(Ex2_UST_ACM!$B$5:$B$194,MATCH(A11,Ex2_UST_ACM!$A$5:$A$194,0)),"") -> 4.1653 | D11: =IF(C11="","",(B11-C11)*100) -> 196.77
A12: 46034 | B12: 6.182 | C12: =IFERROR(INDEX(Ex2_UST_ACM!$B$5:$B$194,MATCH(A12,Ex2_UST_ACM!$A$5:$A$194,0)),"") -> 4.1752 | D12: =IF(C12="","",(B12-C12)*100) -> 200.68
A13: 46035 | B13: 6.197 | C13: =IFERROR(INDEX(Ex2_UST_ACM!$B$5:$B$194,MATCH(A13,Ex2_UST_ACM!$A$5:$A$194,0)),"") -> 4.1792 | D13: =IF(C13="","",(B13-C13)*100) -> 201.78 | F13: Inflasi Indonesia (IDCPI, % YoY) | G13: Nilai
A14: 46036 | B14: 6.239 | C14: =IFERROR(INDEX(Ex2_UST_ACM!$B$5:$B$194,MATCH(A14,Ex2_UST_ACM!$A$5:$A$194,0)),"") -> 4.132 | D14: =IF(C14="","",(B14-C14)*100) -> 210.7 | F14: 45930 | G14: 2.65
A15: 46037 | B15: 6.249 | C15: =IFERROR(INDEX(Ex2_UST_ACM!$B$5:$B$194,MATCH(A15,Ex2_UST_ACM!$A$5:$A$194,0)),"") -> 4.1694 | D15: =IF(C15="","",(B15-C15)*100) -> 207.96 | F15: 45961 | G15: 2.86
A16: 46041 | B16: 6.295 | C16: =IFERROR(INDEX(Ex2_UST_ACM!$B$5:$B$194,MATCH(A16,Ex2_UST_ACM!$A$5:$A$194,0)),"") | D16: =IF(C16="","",(B16-C16)*100) | F16: 45991 | G16: 2.72
A17: 46042 | B17: 6.321 | C17: =IFERROR(INDEX(Ex2_UST_ACM!$B$5:$B$194,MATCH(A17,Ex2_UST_ACM!$A$5:$A$194,0)),"") -> 4.2925 | D17: =IF(C17="","",(B17-C17)*100) -> 202.85 | F17: 46022 | G17: 2.92
A18: 46043 | B18: 6.333 | C18: =IFERROR(INDEX(Ex2_UST_ACM!$B$5:$B$194,MATCH(A18,Ex2_UST_ACM!$A$5:$A$194,0)),"") -> 4.2428 | D18: =IF(C18="","",(B18-C18)*100) -> 209.02 | F18: 46053 | G18: 3.55
A19: 46044 | B19: 6.343 | C19: =IFERROR(INDEX(Ex2_UST_ACM!$B$5:$B$194,MATCH(A19,Ex2_UST_ACM!$A$5:$A$194,0)),"") -> 4.2449 | D19: =IF(C19="","",(B19-C19)*100) -> 209.81 | F19: 46081 | G19: 4.76
A20: 46045 | B20: 6.397 | C20: =IFERROR(INDEX(Ex2_UST_ACM!$B$5:$B$194,MATCH(A20,Ex2_UST_ACM!$A$5:$A$194,0)),"") -> 4.2252 | D20: =IF(C20="","",(B20-C20)*100) -> 217.18 | F20: 46112 | G20: 3.48
A21: 46048 | B21: 6.369 | C21: =IFERROR(INDEX(Ex2_UST_ACM!$B$5:$B$194,MATCH(A21,Ex2_UST_ACM!$A$5:$A$194,0)),"") -> 4.2113 | D21: =IF(C21="","",(B21-C21)*100) -> 215.77 | F21: 46142 | G21: 2.42
A22: 46049 | B22: 6.359 | C22: =IFERROR(INDEX(Ex2_UST_ACM!$B$5:$B$194,MATCH(A22,Ex2_UST_ACM!$A$5:$A$194,0)),"") -> 4.2432 | D22: =IF(C22="","",(B22-C22)*100) -> 211.58 | F22: 46173 | G22: 3.08
A23: 46050 | B23: 6.364 | C23: =IFERROR(INDEX(Ex2_UST_ACM!$B$5:$B$194,MATCH(A23,Ex2_UST_ACM!$A$5:$A$194,0)),"") -> 4.2432 | D23: =IF(C23="","",(B23-C23)*100) -> 212.08 | F23: 46203 | G23: 3.34
A24: 46051 | B24: 6.37 | C24: =IFERROR(INDEX(Ex2_UST_ACM!$B$5:$B$194,MATCH(A24,Ex2_UST_ACM!$A$5:$A$194,0)),"") -> 4.2313 | D24: =IF(C24="","",(B24-C24)*100) -> 213.87 | F24: 46234 | G24: 2.88
A25: 46052 | B25: 6.334 | C25: =IFERROR(INDEX(Ex2_UST_ACM!$B$5:$B$194,MATCH(A25,Ex2_UST_ACM!$A$5:$A$194,0)),"") -> 4.2355 | D25: =IF(C25="","",(B25-C25)*100) -> 209.85 | F25: 46265 | G25: 3.19
A26: 46055 | B26: 6.325 | C26: =IFERROR(INDEX(Ex2_UST_ACM!$B$5:$B$194,MATCH(A26,Ex2_UST_ACM!$A$5:$A$194,0)),"") -> 4.2774 | D26: =IF(C26="","",(B26-C26)*100) -> 204.76 | F26: 46295 | G26: 3.28
A27: 46056 | B27: 6.33 | C27: =IFERROR(INDEX(Ex2_UST_ACM!$B$5:$B$194,MATCH(A27,Ex2_UST_ACM!$A$5:$A$194,0)),"") -> 4.2655 | D27: =IF(C27="","",(B27-C27)*100) -> 206.45 | F27: Real yield FR 10YR (2 Okt) = FR 10YR − inflasi Sep (%) | G27: =G10-G26 -> 3.886
A28: 46057 | B28: 6.31 | C28: =IFERROR(INDEX(Ex2_UST_ACM!$B$5:$B$194,MATCH(A28,Ex2_UST_ACM!$A$5:$A$194,0)),"") -> 4.2735 | D28: =IF(C28="","",(B28-C28)*100) -> 203.65
A29: 46058 | B29: 6.326 | C29: =IFERROR(INDEX(Ex2_UST_ACM!$B$5:$B$194,MATCH(A29,Ex2_UST_ACM!$A$5:$A$194,0)),"") -> 4.1801 | D29: =IF(C29="","",(B29-C29)*100) -> 214.59
A30: 46059 | B30: 6.439 | C30: =IFERROR(INDEX(Ex2_UST_ACM!$B$5:$B$194,MATCH(A30,Ex2_UST_ACM!$A$5:$A$194,0)),"") -> 4.206 | D30: =IF(C30="","",(B30-C30)*100) -> 223.3
A31: 46062 | B31: 6.47 | C31: =IFERROR(INDEX(Ex2_UST_ACM!$B$5:$B$194,MATCH(A31,Ex2_UST_ACM!$A$5:$A$194,0)),"") -> 4.2021 | D31: =IF(C31="","",(B31-C31)*100) -> 226.79
A32: 46063 | B32: 6.45 | C32: =IFERROR(INDEX(Ex2_UST_ACM!$B$5:$B$194,MATCH(A32,Ex2_UST_ACM!$A$5:$A$194,0)),"") -> 4.1427 | D32: =IF(C32="","",(B32-C32)*100) -> 230.73
A33: 46064 | B33: 6.433 | C33: =IFERROR(INDEX(Ex2_UST_ACM!$B$5:$B$194,MATCH(A33,Ex2_UST_ACM!$A$5:$A$194,0)),"") -> 4.1724 | D33: =IF(C33="","",(B33-C33)*100) -> 226.06
A34: 46065 | B34: 6.421 | C34: =IFERROR(INDEX(Ex2_UST_ACM!$B$5:$B$194,MATCH(A34,Ex2_UST_ACM!$A$5:$A$194,0)),"") -> 4.0981 | D34: =IF(C34="","",(B34-C34)*100) -> 232.29
A35: 46066 | B35: 6.402 | C35: =IFERROR(INDEX(Ex2_UST_ACM!$B$5:$B$194,MATCH(A35,Ex2_UST_ACM!$A$5:$A$194,0)),"") -> 4.0483 | D35: =IF(C35="","",(B35-C35)*100) -> 235.37
A36: 46072 | B36: 6.457 | C36: =IFERROR(INDEX(Ex2_UST_ACM!$B$5:$B$194,MATCH(A36,Ex2_UST_ACM!$A$5:$A$194,0)),"") -> 4.0673 | D36: =IF(C36="","",(B36-C36)*100) -> 238.97
A37: 46073 | B37: 6.464 | C37: =IFERROR(INDEX(Ex2_UST_ACM!$B$5:$B$194,MATCH(A37,Ex2_UST_ACM!$A$5:$A$194,0)),"") -> 4.0826 | D37: =IF(C37="","",(B37-C37)*100) -> 238.14
A38: 46076 | B38: 6.453 | C38: =IFERROR(INDEX(Ex2_UST_ACM!$B$5:$B$194,MATCH(A38,Ex2_UST_ACM!$A$5:$A$194,0)),"") -> 4.0309 | D38: =IF(C38="","",(B38-C38)*100) -> 242.21
A39: 46077 | B39: 6.449 | C39: =IFERROR(INDEX(Ex2_UST_ACM!$B$5:$B$194,MATCH(A39,Ex2_UST_ACM!$A$5:$A$194,0)),"") -> 4.029 | D39: =IF(C39="","",(B39-C39)*100) -> 242
... A179: 46297 | B179: 7.166 | C179: =IFERROR(INDEX(Ex2_UST_ACM!$B$5:$B$194,MATCH(A179,Ex2_UST_ACM!$A$5:$A$194,0)),"") -> 5.2706 | D179: =IF(C179="","",(B179-C179)*100) -> 189.54

Sheet Text_Numbers
A1: Angka di teks WMO dan sel sumbernya
A2: Setiap baris menautkan angka di teks ke sel perhitungannya (hijau = link).
A4: Hal. | B4: Paragraf | C4: Angka di teks | D4: Nilai Excel | E4: Satuan / catatan
A5: 1 | B5: Moved, Not Removed | C5: Peluang ≥4,00% Okt: 64,2% → 22,1% | E5: FedMeeting_20261028.csv (25 Sep & 2 Okt) — tidak ada di workbook ini
A6: 1 | B6: Moved, Not Removed | C6: Implied Okt 3,93% | D6: =Ex1_CME_Path!M6 -> 3.92625 | E6: %
A7: 1 | B7: Moved, Not Removed | C7: Implied Des 4,12% | D7: =Ex1_CME_Path!M7 -> 4.11875 | E7: %
A8: 1 | B8: Moved, Not Removed | C8: Implied Des 2027 4,68% | D8: =Ex1_CME_Path!M15 -> 4.6818637 | E8: %
A9: 1 | B9: Moved, Not Removed | C9: P(≥4,00%) Desember 81,7% | D9: =Ex1_CME_Path!L7 -> 0.817 | E9: pecahan
A10: 1 | B10: The Premium Did the Lifting | C10: UST 10YR +11,0 bps | D10: =Ex2_UST_ACM!J5 -> 11.02 | E10: bps
A11: 1 | B11: The Premium Did the Lifting | C11: UST 10YR 5,27% | D11: =Ex2_UST_ACM!J12 -> 5.2706 | E11: %
A12: 1 | B12: The Premium Did the Lifting | C12: Term premium +14,2 bps | D12: =Ex2_UST_ACM!K5 -> 14.22 | E12: bps
A13: 1 | B13: The Premium Did the Lifting | C13: Term premium 0,91% | D13: =Ex2_UST_ACM!J13 -> 0.9137 | E13: %
A14: 1 | B14: The Premium Did the Lifting | C14: YTD: term premium 16,6 dari 110,4 bps | D14: =Ex2_UST_ACM!K8 -> 16.59 | E14: bps (UST 10YR YTD di J8)
A15: 1 | B15: The Premium Did the Lifting | C15: Sejak akhir Juni: +40,8 dari +80,5 bps | D15: =Ex2_UST_ACM!K7 -> 40.75 | E15: bps (UST 10YR di J7)
A16: 1 | B16: Two Ends, Two Stories | C16: UST 2YR −2,7 bps | D16: =Ex2_UST_ACM!M5 -> -2.69 | E16: bps
A17: 1 | B17: Two Ends, Two Stories | C17: 2s10s 30,9 → 44,6 bps | D17: =Ex2_UST_ACM!J15 -> 44.59 | E17: bps (25 Sep di J14)
A18: 2 | B18: Follow the Money | C18: SOX +85,5% YTD | D18: =Ex3_SOX_Hyperscalers!K10 -> 0.85464168 | E18: pecahan
A19: 2 | B19: Follow the Money | C19: Rata-rata hyperscalers +1,5% | D19: =Ex3_SOX_Hyperscalers!K16 -> 0.015497398 | E19: pecahan
A20: 2 | B20: Follow the Money | C20: Oracle −27,0% YTD | D20: =Ex3_SOX_Hyperscalers!K15 -> -0.26991945 | E20: pecahan
A21: 2 | B21: Follow the Money | C21: SOX +3,7% sepekan | D21: =Ex3_SOX_Hyperscalers!M10 -> 0.036920245 | E21: pecahan
A22: 2 | B22: Follow the Money | C22: Micron EPS USD 33,36 vs 2,86 | D22: =P2_Text_Data!B18 -> 33.36 | E22: USD (setahun lalu di B19)
A23: 2 | B23: Follow the Money | C23: Revisi BEst +8,5% | D23: =P2_Text_Data!B22 -> 0.085356349 | E23: pecahan
A24: 2 | B24: Spending on Borrowed Money | C24: Capex 118,63 → 165,05 (+39,1%) | D24: =P2_Text_Data!F8 -> 0.39127723 | E24: pecahan (level di F5, F7)
A25: 2 | B25: Spending on Borrowed Money | C25: Capex Oracle 12,03 → 28,50 | D25: =P2_Text_Data!C15 -> 2.3684036 | E25: kelipatan
A26: 2 | B26: Spending on Borrowed Money | C26: Obligasi 157,00 vs 93,25 (+68,4%) | D26: =Ex4_Hyperscaler_Bonds!G12 -> 0.68364611 | E26: pecahan (level di G9, G10)
A27: 2 | B27: Lenders Read the Balance Sheet | C27: Yield 2036: 5,6% – 7,5%, selisih ±190 bps | D27: =P2_Text_Data!E34 -> 188.33985 | E27: bps
A28: 2 | B28: Lenders Read the Balance Sheet | C28: Sejak akhir Juni: MSFT +38,7% | D28: =Ex3_SOX_Hyperscalers!L12 -> 0.3874055 | E28: pecahan
A29: 2 | B29: Lenders Read the Balance Sheet | C29: Sejak akhir Juni: Meta +29,3% | D29: =Ex3_SOX_Hyperscalers!L14 -> 0.29254913 | E29: pecahan
A30: 2 | B30: Lenders Read the Balance Sheet | C30: Sejak akhir Juni: Oracle −2,9% | D30: =Ex3_SOX_Hyperscalers!L15 -> -0.029000341 | E30: pecahan
A31: 3 | B31: Calm, Not Cheap | C31: USD/IDR September 17.513 – 17.975 | D31: =Ex5_FXR_USDIDR!J8 -> 17513 | E31: terendah (tertinggi di J9)
A32: 3 | B32: Calm, Not Cheap | C32: USD/IDR 17.875 (2 Okt) | D32: =Ex5_FXR_USDIDR!J5 -> 17875 | E32: IDR
A33: 3 | B33: Calm, Not Cheap | C33: Puncak 18.178 (Juni) | D33: =Ex5_FXR_USDIDR!J10 -> 18178 | E33: IDR
A34: 3 | B34: Calm, Not Cheap | C34: Cadangan devisa USD 146,51 miliar | D34: =Ex5_FXR_USDIDR!G5 -> 146.5076 | E34: USD bn
A35: 3 | B35: Calm, Not Cheap | C35: Turun USD 9,96 miliar dari akhir 2025 | D35: =Ex5_FXR_USDIDR!G7 -> -9.9634 | E35: USD bn
A36: 3 | B36: Calm, Not Cheap | C36: Terendah USD 144,90 miliar (Mei) | D36: =Ex5_FXR_USDIDR!G8 -> 144.8984 | E36: USD bn
A37: 3 | B37: Calm, Not Cheap | C37: Rupiah melemah 7,1% YTD | D37: =Ex5_FXR_USDIDR!J7 -> 0.071000599 | E37: pecahan
A38: 3 | B38: One Good Month | C38: Surplus Agustus USD 3,55 miliar | D38: =Ex6_Trade_Balance!G5 -> 3.5522 | E38: USD bn (Juli di G6)
A39: 3 | B39: One Good Month | C39: 12 bulan terakhir USD 19,05 miliar | D39: =Ex6_Trade_Balance!G8 -> 19.0469 | E39: USD bn
A40: 3 | B40: One Good Month | C40: 12 bulan sebelumnya USD 41,67 miliar | D40: =Ex6_Trade_Balance!G9 -> 41.6692 | E40: USD bn
A41: 3 | B41: One Good Month | C41: Jan–Agu 2026 USD 7,25 miliar (−75,3%) | D41: =Ex6_Trade_Balance!G12 -> -0.75291768 | E41: pecahan (level di G10)
...
